Workbook
Name Orders: #REF!
Name People: #REF!
Name Returns: #REF!

Sheet Orders
A1: Row ID | B1: Order ID | C1: Order Date | D1: Ship Date | E1: Ship Mode | F1: Customer ID | G1: Customer Name | H1: Segment | I1: Country/Region | J1: City | K1: State/Province | L1: Postal Code | M1: Region | N1: Product ID | O1: Category | P1: Sub-Category | Q1: Product Name | R1: Sales | S1: Quantity | T1: Discount | U1: Profit
A2: 1 | B2: US-2023-103800 | C2: 44929 | D2: 44933 | E2: Standard Class | F2: DP-13000 | G2: Darren Powers | H2: Consumer | I2: United States | J2: Houston | K2: Texas | L2: 77095 | M2: Central | N2: OFF-PA-10000174 | O2: Office Supplies | P2: Paper | Q2: Message Book, Wirebound, Four 5 1/2" X 4" Forms/Pg., 200 Dupl. Sets/Book | R2: 16.448 | S2: 2 | T2: 0.2 | U2: 5.5512
A3: 2 | B3: US-2023-112326 | C3: 44930 | D3: 44934 | E3: Standard Class | F3: PO-19195 | G3: Phillina Ober | H3: Home Office | I3: United States | J3: Naperville | K3: Illinois | L3: 60540 | M3: Central | N3: OFF-BI-10004094 | O3: Office Supplies | P3: Binders | Q3: GBC Standard Plastic Binding Systems Combs | R3: 3.54 | S3: 2 | T3: 0.8 | U3: -5.487
A4: 3 | B4: US-2023-112326 | C4: 44930 | D4: 44934 | E4: Standard Class | F4: PO-19195 | G4: Phillina Ober | H4: Home Office | I4: United States | J4: Naperville | K4: Illinois | L4: 60540 | M4: Central | N4: OFF-LA-10003223 | O4: Office Supplies | P4: Labels | Q4: Avery 508 | R4: 11.784 | S4: 3 | T4: 0.2 | U4: 4.2717
A5: 4 | B5: US-2023-112326 | C5: 44930 | D5: 44934 | E5: Standard Class | F5: PO-19195 | G5: Phillina Ober | H5: Home Office | I5: United States | J5: Naperville | K5: Illinois | L5: 60540 | M5: Central | N5: OFF-ST-10002743 | O5: Office Supplies | P5: Storage | Q5: SAFCO Boltless Steel Shelving | R5: 272.736 | S5: 3 | T5: 0.2 | U5: -64.7748
A6: 5 | B6: US-2023-141817 | C6: 44931 | D6: 44938 | E6: Standard Class | F6: MB-18085 | G6: Mick Brown | H6: Consumer | I6: United States | J6: Philadelphia | K6: Pennsylvania | L6: 19143 | M6: East | N6: OFF-AR-10003478 | O6: Office Supplies | P6: Art | Q6: Avery Hi-Liter EverBold Pen Style Fluorescent Highlighters, 4/Pack | R6: 19.536 | S6: 3 | T6: 0.2 | U6: 4.884
A7: 6 | B7: US-2023-167199 | C7: 44932 | D7: 44936 | E7: Standard Class | F7: ME-17320 | G7: Maria Etezadi | H7: Home Office | I7: United States | J7: Henderson | K7: Kentucky | L7: 42420 | M7: South | N7: FUR-CH-10004063 | O7: Furniture | P7: Chairs | Q7: Global Deluxe High-Back Manager's Chair | R7: 2573.82 | S7: 9 | T7: 0 | U7: 746.4078
A8: 7 | B8: US-2023-167199 | C8: 44932 | D8: 44936 | E8: Standard Class | F8: ME-17320 | G8: Maria Etezadi | H8: Home Office | I8: United States | J8: Henderson | K8: Kentucky | L8: 42420 | M8: South | N8: OFF-AR-10001662 | O8: Office Supplies | P8: Art | Q8: Rogers Handheld Barrel Pencil Sharpener | R8: 5.48 | S8: 2 | T8: 0 | U8: 1.4796
A9: 8 | B9: US-2023-106054 | C9: 44932 | D9: 44933 | E9: First Class | F9: JO-15145 | G9: Jack O'Briant | H9: Corporate | I9: United States | J9: Athens | K9: Georgia | L9: 30605 | M9: South | N9: OFF-AR-10002399 | O9: Office Supplies | P9: Art | Q9: Dixon Prang Watercolor Pencils, 10-Color Set with Brush | R9: 12.78 | S9: 3 | T9: 0 | U9: 5.2398
A10: 9 | B10: US-2023-167199 | C10: 44932 | D10: 44936 | E10: Standard Class | F10: ME-17320 | G10: Maria Etezadi | H10: Home Office | I10: United States | J10: Henderson | K10: Kentucky | L10: 42420 | M10: South | N10: OFF-BI-10004632 | O10: Office Supplies | P10: Binders | Q10: Ibico Hi-Tech Manual Binding System | R10: 609.98 | S10: 2 | T10: 0 | U10: 274.491
A11: 10 | B11: US-2023-167199 | C11: 44932 | D11: 44936 | E11: Standard Class | F11: ME-17320 | G11: Maria Etezadi | H11: Home Office | I11: United States | J11: Henderson | K11: Kentucky | L11: 42420 | M11: South | N11: OFF-FA-10001883 | O11: Office Supplies | P11: Fasteners | Q11: Alliance Super-Size Bands, Assorted Sizes | R11: 31.12 | S11: 4 | T11: 0 | U11: 0.3112
A12: 11 | B12: US-2023-167199 | C12: 44932 | D12: 44936 | E12: Standard Class | F12: ME-17320 | G12: Maria Etezadi | H12: Home Office | I12: United States | J12: Henderson | K12: Kentucky | L12: 42420 | M12: South | N12: OFF-PA-10000955 | O12: Office Supplies | P12: Paper | Q12: Southworth 25% Cotton Granite Paper & Envelopes | R12: 6.54 | S12: 1 | T12: 0 | U12: 3.0084
A13: 12 | B13: US-2023-130813 | C13: 44932 | D13: 44934 | E13: Second Class | F13: LS-17230 | G13: Lycoris Saunders | H13: Consumer | I13: United States | J13: Los Angeles | K13: California | L13: 90049 | M13: West | N13: OFF-PA-10002005 | O13: Office Supplies | P13: Paper | Q13: Xerox 225 | R13: 19.44 | S13: 3 | T13: 0 | U13: 9.3312
... A62: 61 | B62: US-2023-110422 | C62: 44947 | D62: 44949 | E62: Second Class | F62: TB-21400 | G62: Tom Boeckenhauer | H62: Consumer | I62: United States | J62: Miami | K62: Florida | L62: 33180 | M62: South | N62: FUR-FU-10001889 | O62: Furniture | P62: Furnishings | Q62: Ultra Door Pull Handle | R62: 25.248 | S62: 3 | T62: 0.2 | U62: 4.1028
A63: 62 | B63: CA-2023-115238 | C63: 44947 | D63: 44950 | E63: Standard Class | F63: JW-15220 | G63: Jane Waco | H63: Corporate | I63: Canada | J63: Toronto | K63: Ontario | L63: M7A | M63: East | N63: FUR-FU-10001025 | O63: Furniture | P63: Furnishings | Q63: Eldon Imàge Series Desk Accessories, Clear | R63: 24.3 | S63: 5 | T63: 0 | U63: 10.45
A64: 63 | B64: CA-2023-115238 | C64: 44947 | D64: 44950 | E64: Standard Class | F64: JW-15220 | G64: Jane Waco | H64: Corporate | I64: Canada | J64: Toronto | K64: Ontario | L64: M7A | M64: East | N64: FUR-FU-10002445 | O64: Furniture | P64: Furnishings | Q64: DAX Two-Tone Rosewood/Black Document Frame, Desktop, 5 x 7 | R64: 9.48 | S64: 1 | T64: 0 | U64: 3.79
A65: 64 | B65: CA-2023-115238 | C65: 44947 | D65: 44950 | E65: Standard Class | F65: JW-15220 | G65: Jane Waco | H65: Corporate | I65: Canada | J65: Toronto | K65: Ontario | L65: M7A | M65: East | N65: FUR-FU-10002960 | O65: Furniture | P65: Furnishings | Q65: Eldon 200 Class Desk Accessories, Burgundy | R65: 31.4 | S65: 5 | T65: 0 | U65: 13.19
A66: 65 | B66: CA-2023-115238 | C66: 44947 | D66: 44950 | E66: Standard Class | F66: JW-15220 | G66: Jane Waco | H66: Corporate | I66: Canada | J66: Toronto | K66: Ontario | L66: M7A | M66: East | N66: OFF-PA-10002689 | O66: Office Supplies | P66: Paper | Q66: Weyerhaeuser First Choice Laser/Copy Paper (20Lb. and 88 Bright) | R66: 6.48 | S66: 1 | T66: 0 | U66: 3.11
A67: 66 | B67: CA-2023-115238 | C67: 44947 | D67: 44950 | E67: Standard Class | F67: JW-15220 | G67: Jane Waco | H67: Corporate | I67: Canada | J67: Toronto | K67: Ontario | L67: M7A | M67: East | N67: TEC-PH-10001300 | O67: Technology | P67: Phones | Q67: iKross Bluetooth Portable Keyboard + Cell Phone Stand Holder + Brush for Apple iPhone 5S 5C 5, 4S 4 | R67: 209.5 | S67: 10 | T67: 0 | U67: 58.66
A68: 67 | B68: US-2023-146997 | C68: 44949 | D68: 44953 | E68: Standard Class | F68: SG-20605 | G68: Speros Goranitis | H68: Consumer | I68: United States | J68: Lafayette | K68: Indiana | L68: 47905 | M68: Central | N68: OFF-FA-10003467 | O68: Office Supplies | P68: Fasteners | Q68: Alliance Big Bands Rubber Bands, 12/Pack | R68: 5.94 | S68: 3 | T68: 0 | U68: 0
A69: 68 | B69: US-2023-102645 | C69: 44949 | D69: 44954 | E69: Standard Class | F69: IM-15055 | G69: Ionia McGrath | H69: Consumer | I69: United States | J69: Las Vegas | K69: Nevada | L69: 89115 | M69: West | N69: OFF-PA-10001804 | O69: Office Supplies | P69: Paper | Q69: Xerox 195 | R69: 40.08 | S69: 6 | T69: 0 | U69: 19.2384
A70: 69 | B70: US-2023-167997 | C70: 44952 | D70: 44955 | E70: First Class | F70: CA-11965 | G70: Carol Adams | H70: Corporate | I70: United States | J70: Rapid City | K70: South Dakota | L70: 57701 | M70: Central | N70: FUR-BO-10004409 | O70: Furniture | P70: Bookcases | Q70: Safco Value Mate Series Steel Bookcases, Baked Enamel Finish on Steel, Gray | R70: 141.96 | S70: 2 | T70: 0 | U70: 39.7488
A71: 70 | B71: US-2023-155502 | C71: 44952 | D71: 44957 | E71: Standard Class | F71: SD-20485 | G71: Shirley Daniels | H71: Home Office | I71: United States | J71: Alexandria | K71: Virginia | L71: 22304 | M71: South | N71: FUR-FU-10001847 | O71: Furniture | P71: Furnishings | Q71: Eldon Image Series Black Desk Accessories | R71: 12.42 | S71: 3 | T71: 0 | U71: 4.4712
A72: 71 | B72: US-2023-155502 | C72: 44952 | D72: 44957 | E72: Standard Class | F72: SD-20485 | G72: Shirley Daniels | H72: Home Office | I72: United States | J72: Alexandria | K72: Virginia | L72: 22304 | M72: South | N72: FUR-FU-10004587 | O72: Furniture | P72: Furnishings | Q72: GE General Use Halogen Bulbs, 100 Watts, 1 Bulb per Pack | R72: 62.82 | S72: 3 | T72: 0 | U72: 30.7818
A73: 72 | B73: US-2023-167997 | C73: 44952 | D73: 44955 | E73: First Class | F73: CA-11965 | G73: Carol Adams | H73: Corporate | I73: United States | J73: Rapid City | K73: South Dakota | L73: 57701 | M73: Central | N73: OFF-BI-10001758 | O73: Office Supplies | P73: Binders | Q73: Wilson Jones 14 Line Acrylic Coated Pressboard Data Binders | R73: 10.68 | S73: 2 | T73: 0 | U73: 5.0196
A74: 73 | B74: US-2023-155502 | C74: 44952 | D74: 44957 | E74: Standard Class | F74: SD-20485 | G74: Shirley Daniels | H74: Home Office | I74: United States | J74: Alexandria | K74: Virginia | L74: 22304 | M74: South | N74: OFF-PA-10000380 | O74: Office Supplies | P74: Paper | Q74: REDIFORM Incoming/Outgoing Call Register, 11" X 8 1/2", 100 Messages | R74: 16.68 | S74: 2 | T74: 0 | U74: 8.34
A75: 74 | B75: US-2023-155502 | C75: 44952 | D75: 44957 | E75: Standard Class | F75: SD-20485 | G75: Shirley Daniels | H75: Home Office | I75: United States | J75: Alexandria | K75: Virginia | L75: 22304 | M75: South | N75: OFF-PA-10003072 | O75: Office Supplies | P75: Paper | Q75: Eureka Recycled Copy Paper 8 1/2" x 11", Ream | R75: 19.44 | S75: 3 | T75: 0 | U75: 9.3312
A76: 75 | B76: US-2023-155502 | C76: 44952 | D76: 44957 | E76: Standard Class | F76: SD-20485 | G76: Shirley Daniels | H76: Home Office | I76: United States | J76: Alexandria | K76: Virginia | L76: 22304 | M76: South | N76: OFF-ST-10004337 | O76: Office Supplies | P76: Storage | Q76: SAFCO Commercial Wire Shelving, 72h | R76: 489.92 | S76: 8 | T76: 0 | U76: 0
A77: 76 | B77: US-2023-155502 | C77: 44952 | D77: 44957 | E77: Standard Class | F77: SD-20485 | G77: Shirley Daniels | H77: Home Office | I77: United States | J77: Alexandria | K77: Virginia | L77: 22304 | M77: South | N77: TEC-PH-10002103 | O77: Technology | P77: Phones | Q77: Jabra SPEAK 410 | R77: 187.98 | S77: 2 | T77: 0 | U77: 52.6344
A78: 77 | B78: US-2023-155502 | C78: 44952 | D78: 44957 | E78: Standard Class | F78: SD-20485 | G78: Shirley Daniels | H78: Home Office | I78: United States | J78: Alexandria | K78: Virginia | L78: 22304 | M78: South | N78: TEC-PH-10004833 | O78: Technology | P78: Phones | Q78: Macally Suction Cup Mount | R78: 155.35 | S78: 13 | T78: 0 | U78: 0
A79: 78 | B79: US-2023-117163 | C79: 44953 | D79: 44959 | E79: Standard Class | F79: EJ-13720 | G79: Ed Jacobs | H79: Consumer | I79: United States | J79: San Diego | K79: California | L79: 92037 | M79: West | N79: FUR-TA-10003469 | O79: Furniture | P79: Tables | Q79: Balt Split Level Computer Training Table | R79: 333 | S79: 3 | T79: 0.2 | U79: -16.65
... A180: 179 | B180: US-2023-114790 | C180: 44996 | D180: 44998 | E180: Second Class | F180: FM-14215 | G180: Filia McAdams | H180: Corporate | I180: United States | J180: Richmond | K180: Kentucky | L180: 40475 | M180: South | N180: TEC-PH-10000984 | O180: Technology | P180: Phones | Q180: Panasonic KX-TG9471B | R180: 587.97 | S180: 3 | T180: 0 | U180: 164.6316
A181: 180 | B181: CA-2023-139675 | C181: 44998 | D181: 45003 | E181: Second Class | F181: NF-18595 | G181: Nicole Fjeld | H181: Home Office | I181: Canada | J181: Calgary | K181: Alberta | L181: T2C | M181: West | N181: FUR-CH-10004063 | O181: Furniture | P181: Chairs | Q181: Global Deluxe High-Back Manager's Chair | R181: 915.14 | S181: 4 | T181: 0.2 | U181: 102.95
A182: 181 | B182: CA-2023-139675 | C182: 44998 | D182: 45003 | E182: Second Class | F182: NF-18595 | G182: Nicole Fjeld | H182: Home Office | I182: Canada | J182: Calgary | K182: Alberta | L182: T2C | M182: West | N182: FUR-FU-10001979 | O182: Furniture | P182: Furnishings | Q182: Dana Halogen Swing-Arm Architect Lamp | R182: 327.76 | S182: 8 | T182: 0 | U182: 91.77
A183: 182 | B183: US-2023-125521 | C183: 44999 | D183: 45004 | E183: Standard Class | F183: CK-12325 | G183: Christine Kargatis | H183: Home Office | I183: United States | J183: Chesapeake | K183: Virginia | L183: 23320 | M183: South | N183: FUR-CH-10003379 | O183: Furniture | P183: Chairs | Q183: Global Commerce Series High-Back Swivel/Tilt Chairs | R183: 1139.92 | S183: 4 | T183: 0 | U183: 284.98
A184: 183 | B184: US-2023-157623 | C184: 44999 | D184: 45003 | E184: Standard Class | F184: DK-13225 | G184: Dean Katz | H184: Corporate | I184: United States | J184: Huntington Beach | K184: California | L184: 92646 | M184: West | N184: OFF-AR-10003723 | O184: Office Supplies | P184: Art | Q184: Avery Hi-Liter Fluorescent Desk Style Markers | R184: 3.38 | S184: 1 | T184: 0 | U184: 1.2506
A185: 184 | B185: US-2023-114510 | C185: 44999 | D185: 45004 | E185: Standard Class | F185: JF-15295 | G185: Jason Fortune- | H185: Consumer | I185: United States | J185: Logan | K185: Utah | L185: 84321 | M185: West | N185: OFF-BI-10001617 | O185: Office Supplies | P185: Binders | Q185: GBC Wire Binding Combs | R185: 33.088 | S185: 4 | T185: 0.2 | U185: 11.1672
A186: 185 | B186: US-2023-114510 | C186: 44999 | D186: 45004 | E186: Standard Class | F186: JF-15295 | G186: Jason Fortune- | H186: Consumer | I186: United States | J186: Logan | K186: Utah | L186: 84321 | M186: West | N186: OFF-BI-10003007 | O186: Office Supplies | P186: Binders | Q186: Premium Transparent Presentation Covers, No Pattern/Clear, 8 1/2" x 11" | R186: 62.048 | S186: 2 | T186: 0.2 | U186: 20.1656
A187: 186 | B187: US-2023-100293 | C187: 44999 | D187: 45003 | E187: Standard Class | F187: NF-18475 | G187: Neil Französisch | H187: Home Office | I187: United States | J187: Jacksonville | K187: Florida | L187: 32216 | M187: South | N187: OFF-PA-10000176 | O187: Office Supplies | P187: Paper | Q187: Xerox 1887 | R187: 91.056 | S187: 6 | T187: 0.2 | U187: 31.8696
A188: 187 | B188: US-2023-157623 | C188: 44999 | D188: 45003 | E188: Standard Class | F188: DK-13225 | G188: Dean Katz | H188: Corporate | I188: United States | J188: Huntington Beach | K188: California | L188: 92646 | M188: West | N188: OFF-PA-10001204 | O188: Office Supplies | P188: Paper | Q188: Xerox 1972 | R188: 10.56 | S188: 2 | T188: 0 | U188: 4.752
...

Sheet Lookups
A1: Order Id | B1: Customer Name | C1: Sales | D1: Category | F1: Customer | G1: Total Sales | H1: Order count | I1: 1st 3 Characters | J1: Last 3 characters | K1: Name length | L1: Clean Name | N1: Blank test | O1: Number test
A2: US-2023-103800 | B2: =VLOOKUP(A2,Orders!B:G,6,FALSE) -> Darren Powers | C2: =VLOOKUP(A2,Orders!B:R,17,FALSE) -> 16.448 | D2: =IF(C2>=500,"High","Low") -> Low | F2: =B2 -> Darren Powers | G2: =SUMIFS(Orders!R:R,Orders!G:G,F2) -> 1050.636 | H2: =COUNTIFS(Orders!G:G,Lookups!F2) -> 17 | I2: =LEFT(F2,3) -> Dar | J2: =RIGHT(F2,3) -> ers | K2: =LEN(F2) -> 13 | L2: =TRIM(F2) -> Darren Powers | N2: =IF(A2="","Blank","has value") -> has value | O2: =IF(ISNUMBER(C2),"Number","Text") -> Number
A3: US-2023-112326 | B3: =VLOOKUP(A3,Orders!B:G,6,FALSE) -> Phillina Ober | C3: =VLOOKUP(A3,Orders!B:R,17,FALSE) -> 3.54 | D3: =IF(C3>=500,"High","Low") -> Low | F3: =B3 -> Phillina Ober | G3: =SUMIFS(Orders!R:R,Orders!G:G,F3) -> 1056.858 | H3: =COUNTIFS(Orders!G:G,Lookups!F3) -> 10 | I3: =LEFT(F3,3) -> Phi | J3: =RIGHT(F3,3) -> ber | K3: =LEN(F3) -> 13 | L3: =TRIM(F3) -> Phillina Ober | N3: =IF(A3="","Blank","has value") -> has value | O3: =IF(ISNUMBER(C3),"Number","Text") -> Number
A4: US-2023-112326 | B4: =VLOOKUP(A4,Orders!B:G,6,FALSE) -> Phillina Ober | C4: =VLOOKUP(A4,Orders!B:R,17,FALSE) -> 3.54 | D4: =IF(C4>=500,"High","Low") -> Low | F4: =B4 -> Phillina Ober | G4: =SUMIFS(Orders!R:R,Orders!G:G,F4) -> 1056.858 | H4: =COUNTIFS(Orders!G:G,Lookups!F4) -> 10 | I4: =LEFT(F4,3) -> Phi | J4: =RIGHT(F4,3) -> ber | K4: =LEN(F4) -> 13 | L4: =TRIM(F4) -> Phillina Ober | N4: =IF(A4="","Blank","has value") -> has value | O4: =IF(ISNUMBER(C4),"Number","Text") -> Number
A5: US-2023-112326 | B5: =VLOOKUP(A5,Orders!B:G,6,FALSE) -> Phillina Ober | C5: =VLOOKUP(A5,Orders!B:R,17,FALSE) -> 3.54 | D5: =IF(C5>=500,"High","Low") -> Low | F5: =B5 -> Phillina Ober | G5: =SUMIFS(Orders!R:R,Orders!G:G,F5) -> 1056.858 | H5: =COUNTIFS(Orders!G:G,Lookups!F5) -> 10 | I5: =LEFT(F5,3) -> Phi | J5: =RIGHT(F5,3) -> ber | K5: =LEN(F5) -> 13 | L5: =TRIM(F5) -> Phillina Ober | N5: =IF(A5="","Blank","has value") -> has value | O5: =IF(ISNUMBER(C5),"Number","Text") -> Number
A6: US-2023-141817 | B6: =VLOOKUP(A6,Orders!B:G,6,FALSE) -> Mick Brown | C6: =VLOOKUP(A6,Orders!B:R,17,FALSE) -> 19.536 | D6: =IF(C6>=500,"High","Low") -> Low | F6: =B6 -> Mick Brown | G6: =SUMIFS(Orders!R:R,Orders!G:G,F6) -> 1428.231 | H6: =COUNTIFS(Orders!G:G,Lookups!F6) -> 10 | I6: =LEFT(F6,3) -> Mic | J6: =RIGHT(F6,3) -> own | K6: =LEN(F6) -> 10 | L6: =TRIM(F6) -> Mick Brown | N6: =IF(A7="","Blank","has value") -> Blank | O6: =IF(ISNUMBER(C6),"Number","Text") -> Number

Sheet Formula_Notes
A1: Formula | B1: Purpose | C1: When to use
A2: vlookup | B2: Finds a value from another table | C2: When you need to retrieve related data using a lookup value
A3: if | B3: Returns different results based on a condition | C3: For classifications or logical decisions
A4: sumifs | B4: Adds values based on multiple conditions | C4: To calculate conditional totals
A5: countifs | B5: Counts records based on conditions | C5: To count matching transactions
A6: left | B6: Extracts characters from the beginning | C6: To extract prefixes or codes
A7: right | B7: Extracts characters from the end | C7: To extract suffixes or ending codes
A8: len | B8: Counts characters | C8: To check text length
A9: trim | B9: Removes extra spaces | C9: To clean text data

Sheet People
A1: Regional Manager | B1: Region
A2: Sadie Pawthorne | B2: West
A3: Chuck Magee | B3: East
A4: Roxanne Rodriguez | B4: Central
A5: Fred Suzuki | B5: South

Sheet Returns
A1: Order ID | B1: Returned
A2: US-2023-100762 | B2: Yes
A3: US-2023-100867 | B3: Yes
A4: US-2023-102652 | B4: Yes
A5: US-2023-103373 | B5: Yes
A6: US-2023-103744 | B6: Yes
A7: US-2023-103940 | B7: Yes
A8: US-2023-104829 | B8: Yes
A9: US-2023-105270 | B9: Yes
A10: US-2023-108609 | B10: Yes
A11: US-2023-108861 | B11: Yes
A12: US-2023-109918 | B12: Yes
... A297: US-2026-155999 | B297: Yes
